Traceback (most recent call last):
  File "/opt/homebrew/lib/python3.11/site-packages/wandb/sdk/wandb_config.py", line 165, in __getattr__
    return self.__getitem__(key)
           ^^^^^^^^^^^^^^^^^^^^^
  File "/opt/homebrew/lib/python3.11/site-packages/wandb/sdk/wandb_config.py", line 130, in __getitem__
    return self._items[key]
           ~~~~~~~~~~~^^^^^
KeyError: 'T'

The above exception was the direct cause of the following exception:

Traceback (most recent call last):
  File "/Users/anne/Downloads/College/Year_2/CS_184/final_project/COMPSCI184-Final-Project/civ-environment/env/test.py", line 123, in <module>
    main()
  File "/Users/anne/Downloads/College/Year_2/CS_184/final_project/COMPSCI184-Final-Project/civ-environment/env/test.py", line 91, in main
    score = sweep_train(wandb.config)
            ^^^^^^^^^^^^^^^^^^^^^^^^^
  File "/Users/anne/Downloads/College/Year_2/CS_184/final_project/COMPSCI184-Final-Project/civ-environment/env/test.py", line 82, in sweep_train
    T = config.T,
       ^^^^^^^^
  File "/opt/homebrew/lib/python3.11/site-packages/wandb/sdk/wandb_config.py", line 167, in __getattr__
    raise AttributeError(
AttributeError: <class 'wandb.sdk.wandb_config.Config'> object has no attribute 'T'
